Workbook

Sheet Database
A1: Document_Symbol | B1: Date | C1: Title | D1: WTO_Forum | E1: Participant | F1: Governance function | G1: Domain Family | H1: Reference_Paragraph | I1: Sub-Domain 1 | J1: Sub-Domain 2 | K1: Sub-Domain 3 | L1: Measure | M1: Measure_Owner | N1: Governance Dimension 1 | O1: Governance Topic 1 | P1: Governance Dimension 2 | Q1: Governance Topic 2 | R1: Governance Dimension 3 | S1: Governance Topic 3 | T1: Governance Dimension 4 | U1: Governance Topic 4 | V1: Governance Dimension 5 | W1: Governance Topic 5 | X1: Confidence | Y1: Interaction_Summary
A2: G/C/M/153 | B2: 46177 | C2: Minutes of the Meeting of the Council for Trade in Goods (27-28 Nov 2025) | D2: CTG | E2: India | F2: Information Sharing | G2: Industrial Policy & Economic Security | H2: 9.21 | I2: Export/Import Controls | J2: Carbon Measures | K2: National/Economic Security | L2: No Specific Measure | M2: Not applicable | N2: =_xlfn.XLOOKUP(O2,'Governance Dimension_Topics'!$C$3:$C$16,'Governance Dimension_Topics'!$B$3:$B$16,"None",0) -> Political Economy | O2: Economic Security & Strategic Autonomy | P2: =_xlfn.XLOOKUP(Q2,'Governance Dimension_Topics'!$C$3:$C$16,'Governance Dimension_Topics'!$B$3:$B$16,"None",0) -> Development | Q2: Policy Space | R2: =_xlfn.XLOOKUP(S2,'Governance Dimension_Topics'!$C$3:$C$16,'Governance Dimension_Topics'!$B$3:$B$16,"None",0) -> Political Economy | S2: Economic Security & Strategic Autonomy | X2: High | Y2: Raised concerns that tariffs, NTMs, unilateral green measures and export controls are fragmenting trade and stressing global supply chains.
A3: G/C/M/153 | B3: 46177 | C3: Minutes of the Meeting of the Council for Trade in Goods (27-28 Nov 2025) | D3: CTG | E3: China | F3: Information Sharing | G3: Industrial Policy & Economic Security | H3: 9.23-9.24 | L3: No Specific Measure | M3: Not applicable | N3: =_xlfn.XLOOKUP(O3,'Governance Dimension_Topics'!$C$3:$C$16,'Governance Dimension_Topics'!$B$3:$B$16,"None",0) -> Economic | O3: Market Access & Trade Effects | P3: =_xlfn.XLOOKUP(Q3,'Governance Dimension_Topics'!$C$3:$C$16,'Governance Dimension_Topics'!$B$3:$B$16,"None",0) -> Institutional | Q3: International Cooperation | R3: =_xlfn.XLOOKUP(S3,'Governance Dimension_Topics'!$C$3:$C$16,'Governance Dimension_Topics'!$B$3:$B$16,"None",0) -> Legal | S3: WTO Consistency & Legal Interpretation | X3: High | Y3: Expressed concern over reciprocal tariffs and supported dialogue and WTO reform.
A4: G/C/M/153 | B4: 46177 | C4: Minutes of the Meeting of the Council for Trade in Goods (27-28 Nov 2025) | D4: CTG | E4: Republic of Korea | F4: Information Sharing | G4: Industrial Policy & Economic Security | H4: 9.26 | I4: National/Economic Security | L4: No Specific Measure | M4: Not applicable | N4: =_xlfn.XLOOKUP(O4,'Governance Dimension_Topics'!$C$3:$C$16,'Governance Dimension_Topics'!$B$3:$B$16,"None",0) -> Political Economy | O4: Economic Security & Strategic Autonomy | P4: =_xlfn.XLOOKUP(Q4,'Governance Dimension_Topics'!$C$3:$C$16,'Governance Dimension_Topics'!$B$3:$B$16,"None",0) -> Economic | Q4: Competitiveness | R4: =_xlfn.XLOOKUP(S4,'Governance Dimension_Topics'!$C$3:$C$16,'Governance Dimension_Topics'!$B$3:$B$16,"None",0) -> Legal | S4: Transparency & Due Process | X4: High | Y4: Highlighted negative impacts of trade policy shifts on investment decisions, supply chains and key sectors.
A5: G/C/M/153 | B5: 46177 | C5: Minutes of the Meeting of the Council for Trade in Goods (27-28 Nov 2025) | D5: CTG | E5: Russian Federation | F5: Information Sharing | G5: Industrial Policy & Economic Security | H5: 9.28-9.32 | I5: Export/Import Controls | J5: Carbon Measures | K5: National/Economic Security | L5: No Specific Measure | M5: Not applicable | N5: =_xlfn.XLOOKUP(O5,'Governance Dimension_Topics'!$C$3:$C$16,'Governance Dimension_Topics'!$B$3:$B$16,"None",0) -> Legal | O5: WTO Consistency & Legal Interpretation | P5: =_xlfn.XLOOKUP(Q5,'Governance Dimension_Topics'!$C$3:$C$16,'Governance Dimension_Topics'!$B$3:$B$16,"None",0) -> Legal | Q5: WTO Consistency & Legal Interpretation | R5: =_xlfn.XLOOKUP(S5,'Governance Dimension_Topics'!$C$3:$C$16,'Governance Dimension_Topics'!$B$3:$B$16,"None",0) -> Political Economy | S5: Economic Security & Strategic Autonomy | T5: =_xlfn.XLOOKUP(U5,'Governance Dimension_Topics'!$C$3:$C$16,'Governance Dimension_Topics'!$B$3:$B$16,"None",0) -> Regulatory | U5: Interoperability & Equivalence | X5: Medium | Y5: Criticized unilateral restrictions and regulations justified by environmental protection and national security.
A6: G/C/M/153 | B6: 46177 | C6: Minutes of the Meeting of the Council for Trade in Goods (27-28 Nov 2025) | D6: CTG | E6: Singapore | F6: Information Sharing | G6: Industrial Policy & Economic Security | H6: 9.41-9.42 | I6: National/Economic Security | L6: No Specific Measure | M6: Not applicable | N6: =_xlfn.XLOOKUP(O6,'Governance Dimension_Topics'!$C$3:$C$16,'Governance Dimension_Topics'!$B$3:$B$16,"None",0) -> Political Economy | O6: Economic Security & Strategic Autonomy | P6: =_xlfn.XLOOKUP(Q6,'Governance Dimension_Topics'!$C$3:$C$16,'Governance Dimension_Topics'!$B$3:$B$16,"None",0) -> Institutional | Q6: International Cooperation | R6: =_xlfn.XLOOKUP(S6,'Governance Dimension_Topics'!$C$3:$C$16,'Governance Dimension_Topics'!$B$3:$B$16,"None",0) -> Institutional | S6: Institutional Capacity & Coordination | X6: High | Y6: Called for dialogue, cooperation and WTO reform to address disruptions to supply chains and markets.
A7: G/C/M/153 | B7: 46177 | C7: Minutes of the Meeting of the Council for Trade in Goods (27-28 Nov 2025) | D7: CTG | E7: United States | F7: Information Sharing | G7: Industrial Policy & Economic Security | H7: 9.49-9.55 | I7: National/Economic Security | L7: No Specific Measure | M7: Not applicable | X7: High | Y7: Defended a production-oriented trade policy emphasizing resilience, critical minerals, semiconductors and differentiated trade relationships.
A8: G/C/M/153 | B8: 46177 | C8: Minutes of the Meeting of the Council for Trade in Goods (27-28 Nov 2025) | D8: CTG | E8: Japan | F8: Concern Raised | G8: Climate & Sustainability | H8: 10.3.1 | I8: Other Climate/Sustainability Measures | L8: Fluorinated GHG Reg. | M8: European Union | N8: =_xlfn.XLOOKUP(O8,'Governance Dimension_Topics'!$C$3:$C$16,'Governance Dimension_Topics'!$B$3:$B$16,"None",0) -> Technical | O8: Technical Basis | P8: =_xlfn.XLOOKUP(Q8,'Governance Dimension_Topics'!$C$3:$C$16,'Governance Dimension_Topics'!$B$3:$B$16,"None",0) -> Legal | Q8: WTO Consistency & Legal Interpretation | X8: High | Y8: Raised concerns regarding EU F-Gas regulation and transition impacts.
A9: G/C/M/153 | B9: 46177 | C9: Minutes of the Meeting of the Council for Trade in Goods (27-28 Nov 2025) | D9: CTG | E9: United States | F9: Concern Raised | G9: Climate & Sustainability | H9: 10.3.1 | I9: Other Climate/Sustainability Measures | L9: Fluorinated GHG Reg. | M9: European Union | N9: =_xlfn.XLOOKUP(O9,'Governance Dimension_Topics'!$C$3:$C$16,'Governance Dimension_Topics'!$B$3:$B$16,"None",0) -> Economic | O9: Market Access & Trade Effects | P9: =_xlfn.XLOOKUP(Q9,'Governance Dimension_Topics'!$C$3:$C$16,'Governance Dimension_Topics'!$B$3:$B$16,"None",0) -> Economic | Q9: Market Access & Trade Effects | X9: High | Y9: Supported concerns regarding EU F-Gas regulation.
A10: G/C/M/153 | B10: 46177 | C10: Minutes of the Meeting of the Council for Trade in Goods (27-28 Nov 2025) | D10: CTG | E10: European Union | F10: Defence/Explanation | G10: Climate & Sustainability | H10: 10.3.1 | I10: Other Climate/Sustainability Measures | J10: Other Climate/Sustainability Measures | L10: Fluorinated GHG Reg. | M10: European Union | X10: High | Y10: Defended the F-Gas regulation and its climate objectives.
A11: G/C/M/153 | B11: 46177 | C11: Minutes of the Meeting of the Council for Trade in Goods (27-28 Nov 2025) | D11: CTG | E11: United States | F11: Concern Raised | G11: Climate & Sustainability | H11: 10.3.2 | I11: Other Climate/Sustainability Measures | L11: MRLs | M11: European Union | N11: =_xlfn.XLOOKUP(O11,'Governance Dimension_Topics'!$C$3:$C$16,'Governance Dimension_Topics'!$B$3:$B$16,"None",0) -> Legal | O11: WTO Consistency & Legal Interpretation | P11: =_xlfn.XLOOKUP(Q11,'Governance Dimension_Topics'!$C$3:$C$16,'Governance Dimension_Topics'!$B$3:$B$16,"None",0) -> Economic | Q11: Market Access & Trade Effects | X11: High | Y11: Raised concerns over EU pesticide residue rules.
A12: G/C/M/153 | B12: 46177 | C12: Minutes of the Meeting of the Council for Trade in Goods (27-28 Nov 2025) | D12: CTG | E12: Brazil | F12: Concern Raised | G12: Climate & Sustainability | H12: 10.3.2 | I12: Other Climate/Sustainability Measures | L12: MRLs | M12: European Union | N12: =_xlfn.XLOOKUP(O12,'Governance Dimension_Topics'!$C$3:$C$16,'Governance Dimension_Topics'!$B$3:$B$16,"None",0) -> Technical | O12: Technical Basis | P12: =_xlfn.XLOOKUP(Q12,'Governance Dimension_Topics'!$C$3:$C$16,'Governance Dimension_Topics'!$B$3:$B$16,"None",0) -> Economic | Q12: Market Access & Trade Effects | R12: =_xlfn.XLOOKUP(S12,'Governance Dimension_Topics'!$C$3:$C$16,'Governance Dimension_Topics'!$B$3:$B$16,"None",0) -> Legal | S12: Transparency & Due Process | T12: =_xlfn.XLOOKUP(U12,'Governance Dimension_Topics'!$C$3:$C$16,'Governance Dimension_Topics'!$B$3:$B$16,"None",0) -> Development | U12: Policy Space | X12: High | Y12: Questioned scientific justification.
A13: G/C/M/153 | B13: 46177 | C13: Minutes of the Meeting of the Council for Trade in Goods (27-28 Nov 2025) | D13: CTG | E13: Australia | F13: Concern Raised | G13: Climate & Sustainability | H13: 10.3.2 | I13: Other Climate/Sustainability Measures | L13: MRLs | M13: European Union | N13: =_xlfn.XLOOKUP(O13,'Governance Dimension_Topics'!$C$3:$C$16,'Governance Dimension_Topics'!$B$3:$B$16,"None",0) -> Economic | O13: Market Access & Trade Effects | P13: =_xlfn.XLOOKUP(Q13,'Governance Dimension_Topics'!$C$3:$C$16,'Governance Dimension_Topics'!$B$3:$B$16,"None",0) -> Development | Q13: Policy Space | X13: Medium | Y13: Raised trade concerns regarding implementation.
A14: G/C/M/153 | B14: 46177 | C14: Minutes of the Meeting of the Council for Trade in Goods (27-28 Nov 2025) | D14: CTG | E14: Indonesia | F14: Concern Raised | G14: Climate & Sustainability | H14: 10.3.2 | I14: Other Climate/Sustainability Measures | L14: MRLs | M14: European Union | N14: =_xlfn.XLOOKUP(O14,'Governance Dimension_Topics'!$C$3:$C$16,'Governance Dimension_Topics'!$B$3:$B$16,"None",0) -> Development | O14: Policy Space | P14: =_xlfn.XLOOKUP(Q14,'Governance Dimension_Topics'!$C$3:$C$16,'Governance Dimension_Topics'!$B$3:$B$16,"None",0) -> Legal | Q14: WTO Consistency & Legal Interpretation | R14: =_xlfn.XLOOKUP(S14,'Governance Dimension_Topics'!$C$3:$C$16,'Governance Dimension_Topics'!$B$3:$B$16,"None",0) -> Economic | S14: Market Access & Trade Effects | X14: Medium | Y14: Expressed concern regarding impacts on exporters.
A15: G/C/M/153 | B15: 46177 | C15: Minutes of the Meeting of the Council for Trade in Goods (27-28 Nov 2025) | D15: CTG | E15: Argentina | F15: Concern Raised | G15: Climate & Sustainability | H15: 10.3.2 | I15: Other Climate/Sustainability Measures | L15: MRLs | M15: European Union | N15: =_xlfn.XLOOKUP(O15,'Governance Dimension_Topics'!$C$3:$C$16,'Governance Dimension_Topics'!$B$3:$B$16,"None",0) -> Technical | O15: Technical Basis | X15: High | Y15: Supported concerns regarding scientific basis.
A16: G/C/M/153 | B16: 46177 | C16: Minutes of the Meeting of the Council for Trade in Goods (27-28 Nov 2025) | D16: CTG | E16: Ecuador | F16: Concern Raised | G16: Climate & Sustainability | H16: 10.3.2 | I16: Other Climate/Sustainability Measures | L16: MRLs | M16: European Union | N16: =_xlfn.XLOOKUP(O16,'Governance Dimension_Topics'!$C$3:$C$16,'Governance Dimension_Topics'!$B$3:$B$16,"None",0) -> Economic | O16: Market Access & Trade Effects | P16: =_xlfn.XLOOKUP(Q16,'Governance Dimension_Topics'!$C$3:$C$16,'Governance Dimension_Topics'!$B$3:$B$16,"None",0) -> Legal | Q16: WTO Consistency & Legal Interpretation | R16: =_xlfn.XLOOKUP(S16,'Governance Dimension_Topics'!$C$3:$C$16,'Governance Dimension_Topics'!$B$3:$B$16,"None",0) -> Development | S16: Policy Space | X16: Medium | Y16: Supported co-sponsors' concerns.
A17: G/C/M/153 | B17: 46177 | C17: Minutes of the Meeting of the Council for Trade in Goods (27-28 Nov 2025) | D17: CTG | E17: Paraguay | F17: Concern Raised | G17: Climate & Sustainability | H17: 10.3.2 | I17: Other Climate/Sustainability Measures | L17: MRLs | M17: European Union | N17: =_xlfn.XLOOKUP(O17,'Governance Dimension_Topics'!$C$3:$C$16,'Governance Dimension_Topics'!$B$3:$B$16,"None",0) -> Economic | O17: Market Access & Trade Effects | P17: =_xlfn.XLOOKUP(Q17,'Governance Dimension_Topics'!$C$3:$C$16,'Governance Dimension_Topics'!$B$3:$B$16,"None",0) -> Legal | Q17: WTO Consistency & Legal Interpretation | R17: =_xlfn.XLOOKUP(S17,'Governance Dimension_Topics'!$C$3:$C$16,'Governance Dimension_Topics'!$B$3:$B$16,"None",0) -> Legal | S17: WTO Consistency & Legal Interpretation | T17: =_xlfn.XLOOKUP(U17,'Governance Dimension_Topics'!$C$3:$C$16,'Governance Dimension_Topics'!$B$3:$B$16,"None",0) -> Technical | U17: Technical Basis | X17: Medium | Y17: Supported co-sponsors' concerns.
A18: G/C/M/153 | B18: 46177 | C18: Minutes of the Meeting of the Council for Trade in Goods (27-28 Nov 2025) | D18: CTG | E18: Guatemala | F18: Concern Raised | G18: Climate & Sustainability | H18: 10.3.2 | I18: Other Climate/Sustainability Measures | L18: MRLs | M18: European Union | N18: =_xlfn.XLOOKUP(O18,'Governance Dimension_Topics'!$C$3:$C$16,'Governance Dimension_Topics'!$B$3:$B$16,"None",0) -> Economic | O18: Market Access & Trade Effects | P18: =_xlfn.XLOOKUP(Q18,'Governance Dimension_Topics'!$C$3:$C$16,'Governance Dimension_Topics'!$B$3:$B$16,"None",0) -> Legal | Q18: WTO Consistency & Legal Interpretation | X18: Medium | Y18: Supported concerns on residue measures.
A19: G/C/M/153 | B19: 46177 | C19: Minutes of the Meeting of the Council for Trade in Goods (27-28 Nov 2025) | D19: CTG | E19: India | F19: Concern Raised | G19: Climate & Sustainability | H19: 10.3.2 | I19: Other Climate/Sustainability Measures | L19: MRLs | M19: European Union | N19: =_xlfn.XLOOKUP(O19,'Governance Dimension_Topics'!$C$3:$C$16,'Governance Dimension_Topics'!$B$3:$B$16,"None",0) -> Technical | O19: Technical Basis | X19: Medium | Y19: Raised concerns on implementation and evidence base.
A20: G/C/M/153 | B20: 46177 | C20: Minutes of the Meeting of the Council for Trade in Goods (27-28 Nov 2025) | D20: CTG | E20: Colombia | F20: Concern Raised | G20: Climate & Sustainability | H20: 10.3.2 | I20: Other Climate/Sustainability Measures | L20: MRLs | M20: European Union | N20: =_xlfn.XLOOKUP(O20,'Governance Dimension_Topics'!$C$3:$C$16,'Governance Dimension_Topics'!$B$3:$B$16,"None",0) -> Economic | O20: Market Access & Trade Effects | P20: =_xlfn.XLOOKUP(Q20,'Governance Dimension_Topics'!$C$3:$C$16,'Governance Dimension_Topics'!$B$3:$B$16,"None",0) -> Technical | Q20: Technical Basis | X20: Medium | Y20: Supported concerns raised by exporters.
A21: G/C/M/153 | B21: 46177 | C21: Minutes of the Meeting of the Council for Trade in Goods (27-28 Nov 2025) | D21: CTG | E21: Uruguay | F21: Concern Raised | G21: Climate & Sustainability | H21: 10.3.2 | I21: Other Climate/Sustainability Measures | L21: MRLs | M21: European Union | N21: =_xlfn.XLOOKUP(O21,'Governance Dimension_Topics'!$C$3:$C$16,'Governance Dimension_Topics'!$B$3:$B$16,"None",0) -> Economic | O21: Market Access & Trade Effects | P21: =_xlfn.XLOOKUP(Q21,'Governance Dimension_Topics'!$C$3:$C$16,'Governance Dimension_Topics'!$B$3:$B$16,"None",0) -> Legal | Q21: WTO Consistency & Legal Interpretation | R21: =_xlfn.XLOOKUP(S21,'Governance Dimension_Topics'!$C$3:$C$16,'Governance Dimension_Topics'!$B$3:$B$16,"None",0) -> Development | S21: Policy Space | X21: Medium | Y21: Supported concerns regarding agricultural exports.
A22: G/C/M/153 | B22: 46177 | C22: Minutes of the Meeting of the Council for Trade in Goods (27-28 Nov 2025) | D22: CTG | E22: Canada | F22: Concern Raised | G22: Climate & Sustainability | H22: 10.3.2 | I22: Other Climate/Sustainability Measures | L22: MRLs | M22: European Union | N22: =_xlfn.XLOOKUP(O22,'Governance Dimension_Topics'!$C$3:$C$16,'Governance Dimension_Topics'!$B$3:$B$16,"None",0) -> Economic | O22: Market Access & Trade Effects | P22: =_xlfn.XLOOKUP(Q22,'Governance Dimension_Topics'!$C$3:$C$16,'Governance Dimension_Topics'!$B$3:$B$16,"None",0) -> Technical | Q22: Technical Basis | X22: Medium | Y22: Supported concerns regarding trade impacts.
A23: G/C/M/153 | B23: 46177 | C23: Minutes of the Meeting of the Council for Trade in Goods (27-28 Nov 2025) | D23: CTG | E23: European Union | F23: Defence/Explanation | G23: Climate & Sustainability | H23: 10.3.2 | I23: Other Climate/Sustainability Measures | L23: MRLs | M23: European Union | X23: High | Y23: Defended the regulation and underlying risk assessment.
A24: G/C/M/153 | B24: 46177 | C24: Minutes of the Meeting of the Council for Trade in Goods (27-28 Nov 2025) | D24: CTG | E24: European Union | F24: Concern Raised | G24: Industrial Policy & Economic Security | H24: 10.3.8 | I24: Export/Import Controls | L24: Export Controls on Strategic Products | M24: China | N24: =_xlfn.XLOOKUP(O24,'Governance Dimension_Topics'!$C$3:$C$16,'Governance Dimension_Topics'!$B$3:$B$16,"None",0) -> Political Economy | O24: Economic Security & Strategic Autonomy | P24: =_xlfn.XLOOKUP(Q24,'Governance Dimension_Topics'!$C$3:$C$16,'Governance Dimension_Topics'!$B$3:$B$16,"None",0) -> Legal | Q24: WTO Consistency & Legal Interpretation | R24: =_xlfn.XLOOKUP(S24,'Governance Dimension_Topics'!$C$3:$C$16,'Governance Dimension_Topics'!$B$3:$B$16,"None",0) -> Legal | S24: WTO Consistency & Legal Interpretation | X24: High | Y24: Raised concerns regarding China's export control law and strategic product restrictions.
A25: G/C/M/153 | B25: 46177 | C25: Minutes of the Meeting of the Council for Trade in Goods (27-28 Nov 2025) | D25: CTG | E25: India | F25: Concern Raised | G25: Industrial Policy & Economic Security | H25: 10.3.8 | I25: Export/Import Controls | L25: Export Controls on Strategic Products | M25: China | N25: =_xlfn.XLOOKUP(O25,'Governance Dimension_Topics'!$C$3:$C$16,'Governance Dimension_Topics'!$B$3:$B$16,"None",0) -> Economic | O25: Market Access & Trade Effects
A26: G/C/M/153 | B26: 46177 | C26: Minutes of the Meeting of the Council for Trade in Goods (27-28 Nov 2025) | D26: CTG | E26: United States | F26: Concern Raised | G26: Industrial Policy & Economic Security | H26: 10.3.8 | I26: Export/Import Controls | L26: Export Controls on Strategic Products | M26: China | N26: =_xlfn.XLOOKUP(O26,'Governance Dimension_Topics'!$C$3:$C$16,'Governance Dimension_Topics'!$B$3:$B$16,"None",0) -> Legal | O26: Transparency & Due Process
A27: G/C/M/153 | B27: 46177 | C27: Minutes of the Meeting of the Council for Trade in Goods (27-28 Nov 2025) | D27: CTG | E27: Australia | F27: Concern Raised | G27: Industrial Policy & Economic Security | H27: 10.3.8 | I27: Export/Import Controls | L27: Export Controls on Strategic Products | M27: China | N27: =_xlfn.XLOOKUP(O27,'Governance Dimension_Topics'!$C$3:$C$16,'Governance Dimension_Topics'!$B$3:$B$16,"None",0) -> Economic | O27: Market Access & Trade Effects
A28: G/C/M/153 | B28: 46177 | C28: Minutes of the Meeting of the Council for Trade in Goods (27-28 Nov 2025) | D28: CTG | E28: Canada | F28: Concern Raised | G28: Industrial Policy & Economic Security | H28: 10.3.8 | I28: Export/Import Controls | L28: Export Controls on Strategic Products | M28: China | N28: =_xlfn.XLOOKUP(O28,'Governance Dimension_Topics'!$C$3:$C$16,'Governance Dimension_Topics'!$B$3:$B$16,"None",0) -> Economic | O28: Market Access & Trade Effects
A29: G/C/M/153 | B29: 46177 | C29: Minutes of the Meeting of the Council for Trade in Goods (27-28 Nov 2025) | D29: CTG | E29: Norway | F29: Concern Raised | G29: Industrial Policy & Economic Security | H29: 10.3.8 | I29: Export/Import Controls | L29: Export Controls on Strategic Products | M29: China | N29: =_xlfn.XLOOKUP(O29,'Governance Dimension_Topics'!$C$3:$C$16,'Governance Dimension_Topics'!$B$3:$B$16,"None",0) -> Legal | O29: Transparency & Due Process | P29: =_xlfn.XLOOKUP(Q29,'Governance Dimension_Topics'!$C$3:$C$16,'Governance Dimension_Topics'!$B$3:$B$16,"None",0) -> Economic | Q29: Market Access & Trade Effects
A30: G/C/M/153 | B30: 46177 | C30: Minutes of the Meeting of the Council for Trade in Goods (27-28 Nov 2025) | D30: CTG | E30: Switzerland | F30: Concern Raised | G30: Industrial Policy & Economic Security | H30: 10.3.8 | I30: Export/Import Controls | L30: Export Controls on Strategic Products | M30: China | N30: =_xlfn.XLOOKUP(O30,'Governance Dimension_Topics'!$C$3:$C$16,'Governance Dimension_Topics'!$B$3:$B$16,"None",0) -> Legal | O30: WTO Consistency & Legal Interpretation | P30: =_xlfn.XLOOKUP(Q30,'Governance Dimension_Topics'!$C$3:$C$16,'Governance Dimension_Topics'!$B$3:$B$16,"None",0) -> Legal | Q30: Transparency & Due Process | R30: =_xlfn.XLOOKUP(S30,'Governance Dimension_Topics'!$C$3:$C$16,'Governance Dimension_Topics'!$B$3:$B$16,"None",0) -> Economic | S30: Market Access & Trade Effects
A31: G/C/M/153 | B31: 46177 | C31: Minutes of the Meeting of the Council for Trade in Goods (27-28 Nov 2025) | D31: CTG | E31: United Kingdom | F31: Concern Raised | G31: Industrial Policy & Economic Security | H31: 10.3.8 | I31: Export/Import Controls | L31: Export Controls on Strategic Products | M31: China | N31: =_xlfn.XLOOKUP(O31,'Governance Dimension_Topics'!$C$3:$C$16,'Governance Dimension_Topics'!$B$3:$B$16,"None",0) -> Legal | O31: Transparency & Due Process | P31: =_xlfn.XLOOKUP(Q31,'Governance Dimension_Topics'!$C$3:$C$16,'Governance Dimension_Topics'!$B$3:$B$16,"None",0) -> Economic | Q31: Market Access & Trade Effects
A32: G/C/M/153 | B32: 46177 | C32: Minutes of the Meeting of the Council for Trade in Goods (27-28 Nov 2025) | D32: CTG | E32: China | F32: Defence/Explanation | G32: Industrial Policy & Economic Security | H32: 10.3.8 | I32: Export/Import Controls | L32: Export Controls on Strategic Products | M32: China
A33: G/C/M/153 | B33: 46177 | C33: Minutes of the Meeting of the Council for Trade in Goods (27-28 Nov 2025) | D33: CTG | E33: Japan | F33: Concern Raised | G33: Industrial Policy & Economic Security | H33: 10.3.8 | I33: Export/Import Controls | J33: National/Economic Security | L33: Export Controls on Strategic Products | M33: China | N33: =_xlfn.XLOOKUP(O33,'Governance Dimension_Topics'!$C$3:$C$16,'Governance Dimension_Topics'!$B$3:$B$16,"None",0) -> Political Economy | O33: Economic Security & Strategic Autonomy | P33: =_xlfn.XLOOKUP(Q33,'Governance Dimension_Topics'!$C$3:$C$16,'Governance Dimension_Topics'!$B$3:$B$16,"None",0) -> Legal | Q33: Transparency & Due Process | R33: =_xlfn.XLOOKUP(S33,'Governance Dimension_Topics'!$C$3:$C$16,'Governance Dimension_Topics'!$B$3:$B$16,"None",0) -> Legal | S33: WTO Consistency & Legal Interpretation | X33: High | Y33: Raised concerns regarding impacts on supply chains.
A34: G/C/M/153 | B34: 46177 | C34: Minutes of the Meeting of the Council for Trade in Goods (27-28 Nov 2025) | D34: CTG | E34: China | F34: Defence/Explanation | G34: Industrial Policy & Economic Security | H34: 10.3.8 | I34: Export/Import Controls | J34: National/Economic Security | L34: Export Controls on Strategic Products | M34: China | X34: High | Y34: Defended export control measures as legitimate and security-related.
A35: G/C/M/153 | B35: 46177 | C35: Minutes of the Meeting of the Council for Trade in Goods (27-28 Nov 2025) | D35: CTG | E35: Republic of Korea | F35: Concern Raised | G35: Industrial Policy & Economic Security | H35: 10.3.13 | I35: Subsidies | L35: EV Scheme (France) | M35: France | N35: =_xlfn.XLOOKUP(O35,'Governance Dimension_Topics'!$C$3:$C$16,'Governance Dimension_Topics'!$B$3:$B$16,"None",0) -> Political Economy | O35: Economic Security & Strategic Autonomy | P35: =_xlfn.XLOOKUP(Q35,'Governance Dimension_Topics'!$C$3:$C$16,'Governance Dimension_Topics'!$B$3:$B$16,"None",0) -> Legal | Q35: WTO Consistency & Legal Interpretation | X35: High | Y35: Raised concerns regarding French EV subsidy scheme and discriminatory design.
A36: G/C/M/153 | B36: 46177 | C36: Minutes of the Meeting of the Council for Trade in Goods (27-28 Nov 2025) | D36: CTG | E36: European Union | F36: Defence/Explanation | G36: Industrial Policy & Economic Security | H36: 10.3.13 | I36: Subsidies | L36: EV Scheme (France) | M36: France | X36: High | Y36: Defended EV subsidy scheme and environmental criteria.
A37: G/C/M/153 | B37: 46177 | C37: Minutes of the Meeting of the Council for Trade in Goods (27-28 Nov 2025) | D37: CTG | E37: Argentina | F37: Concern Raised | G37: Climate & Sustainability | H37: 10.3.14 | I37: Carbon Measures | L37: EU CBAM | M37: European Union | N37: =_xlfn.XLOOKUP(O37,'Governance Dimension_Topics'!$C$3:$C$16,'Governance Dimension_Topics'!$B$3:$B$16,"None",0) -> Economic | O37: Market Access & Trade Effects | P37: =_xlfn.XLOOKUP(Q37,'Governance Dimension_Topics'!$C$3:$C$16,'Governance Dimension_Topics'!$B$3:$B$16,"None",0) -> Legal | Q37: WTO Consistency & Legal Interpretation | R37: =_xlfn.XLOOKUP(S37,'Governance Dimension_Topics'!$C$3:$C$16,'Governance Dimension_Topics'!$B$3:$B$16,"None",0) -> Technical | S37: Technical Basis | X37: High | Y37: Concern over CBAM trade effects on developing country exports and climate-trade balance.
A38: G/C/M/153 | B38: 46177 | C38: Minutes of the Meeting of the Council for Trade in Goods (27-28 Nov 2025) | D38: CTG | E38: Brazil | F38: Concern Raised | G38: Climate & Sustainability | H38: 10.3.14 | I38: Carbon Measures | L38: EU CBAM | M38: European Union | N38: =_xlfn.XLOOKUP(O38,'Governance Dimension_Topics'!$C$3:$C$16,'Governance Dimension_Topics'!$B$3:$B$16,"None",0) -> Development | O38: Equity & Just Transition | P38: =_xlfn.XLOOKUP(Q38,'Governance Dimension_Topics'!$C$3:$C$16,'Governance Dimension_Topics'!$B$3:$B$16,"None",0) -> Legal | Q38: WTO Consistency & Legal Interpretation | R38: =_xlfn.XLOOKUP(S38,'Governance Dimension_Topics'!$C$3:$C$16,'Governance Dimension_Topics'!$B$3:$B$16,"None",0) -> Development | S38: Policy Space | X38: High | Y38: Argued CBAM disregards CBDR principles and unfairly shifts burden to developing countries.
A39: G/C/M/153 | B39: 46177 | C39: Minutes of the Meeting of the Council for Trade in Goods (27-28 Nov 2025) | D39: CTG | E39: China | F39: Concern Raised | G39: Climate & Sustainability | H39: 10.3.14 | I39: Carbon Measures | L39: EU CBAM | M39: European Union | N39: =_xlfn.XLOOKUP(O39,'Governance Dimension_Topics'!$C$3:$C$16,'Governance Dimension_Topics'!$B$3:$B$16,"None",0) -> Legal | O39: WTO Consistency & Legal Interpretation | P39: =_xlfn.XLOOKUP(Q39,'Governance Dimension_Topics'!$C$3:$C$16,'Governance Dimension_Topics'!$B$3:$B$16,"None",0) -> Development | Q39: Equity & Just Transition | R39: =_xlfn.XLOOKUP(S39,'Governance Dimension_Topics'!$C$3:$C$16,'Governance Dimension_Topics'!$B$3:$B$16,"None",0) -> Economic | S39: Market Access & Trade Effects | T39: =_xlfn.XLOOKUP(U39,'Governance Dimension_Topics'!$C$3:$C$16,'Governance Dimension_Topics'!$B$3:$B$16,"None",0) -> Regulatory | U39: Interoperability & Equivalence | X39: High | Y39: Questioned compatibility of CBAM with multilateral trade rules and non-discrimination.
A40: G/C/M/153 | B40: 46177 | C40: Minutes of the Meeting of the Council for Trade in Goods (27-28 Nov 2025) | D40: CTG | E40: Indonesia | F40: Concern Raised | G40: Climate & Sustainability | H40: 10.3.14 | I40: Carbon Measures | L40: EU CBAM | M40: European Union | N40: =_xlfn.XLOOKUP(O40,'Governance Dimension_Topics'!$C$3:$C$16,'Governance Dimension_Topics'!$B$3:$B$16,"None",0) -> Development | O40: Equity & Just Transition | P40: =_xlfn.XLOOKUP(Q40,'Governance Dimension_Topics'!$C$3:$C$16,'Governance Dimension_Topics'!$B$3:$B$16,"None",0) -> Legal | Q40: WTO Consistency & Legal Interpretation | R40: =_xlfn.XLOOKUP(S40,'Governance Dimension_Topics'!$C$3:$C$16,'Governance Dimension_Topics'!$B$3:$B$16,"None",0) -> Economic | S40: Market Access & Trade Effects | T40: =_xlfn.XLOOKUP(U40,'Governance Dimension_Topics'!$C$3:$C$16,'Governance Dimension_Topics'!$B$3:$B$16,"None",0) -> Regulatory | U40: Interoperability & Equivalence | X40: High | Y40: Raised concerns regarding impacts on industrialization and policy autonomy.
...

Sheet Domain
A1: Domain | B1: Sub-Domain | C1: Keywords / Alternative Terms
A2: Climate & Sustainability | B2: Carbon Measures | C2: CBAM; Carbon Border Adjustment; Carbon Border Adjustment Mechanism; Border Carbon Adjustment; Border Carbon Measures; Decarbonization; Decarbonisation; Net Zero
A3: Climate & Sustainability | B3: Deforestation & Biodiversity | C3: EUDR; Deforestation Regulation; Forest Risk Commodities; Biodiversity; Nature Protection; Ecosystem Protection
A4: Climate & Sustainability | B4: Other Climate/ Sustainability Measures | C4: Circular Economy; Eco-design; Ecodesign; Product Passport; Recycling Requirements; Recycled Content; Sustainability Standards; ESG Standards; Sustainability Reporting; Disclosure Requirements; Due Diligence; Supply Chain Due Diligence; Sustainability Standards; ESG Standards; Sustainability Reporting; Disclosure Requirements; Due Diligence; Supply Chain Due Diligence; Energy Transition; Green Hydrogen; Renewable Energy
A5: Digital Trade | B5: AI & Emerging Technologies | C5: Artificial Intelligence; AI; Algorithmic Systems; Machine Learning; Cybersecurity; Cyber Security; Digital Security
A6: Digital Trade | B6: E-Commerce | C6: E-Commerce; Electronic Commerce; Digital Trade; Online Platforms; Moratorium; Customs Duties on Electronic Transmissions; Electronic Transmissions; Cross-Border Data Flows; Data Transfers; Data Localisation; Data Localization; Data Governance
A7: Industrial Policy & Economic Security | B7: Subsidies | C7: Subsidies; State Aid; Government Support; Fiscal Incentives; Tax Credits; State Interventions
A8: Industrial Policy & Economic Security | B8: Green Policies | C8: Inflation Reduction Act; IRA; Clean Technology Support; Industrial Decarbonisation; Net-Zero Industry Policies
A9: Industrial Policy & Economic Security | B9: Localisation Measures | C9: Local Content Requirements; Domestic Content Requirements; Localization Requirements; Import Substitution
A10: Industrial Policy & Economic Security | B10: Government Procurement | C10: Public Procurement; Government Procurement; Buy National; Buy Local
A11: Industrial Policy & Economic Security | B11: National/Economic Security | C11: Critical Minerals; Rare Earths; Strategic Raw Materials; Supply Chain Resilience; Diversification; Friendshoring; Nearshoring; Trade Weaponisation
A12: Industrial Policy & Economic Security | B12: Export/Import Controls | C12: Export Controls; Export Restrictions; Technology Controls; Semiconductor Controls; Import Restrictions

Sheet Governance Dimension_Topics
B2: Governance Dimension | C2: Governance Topic | D2: Trigger Keywords | E2: Contextual Indicators
B3: Legal | C3: WTO Consistency & Legal Interpretation | D3: WTO-consistent, obligations, GATT, SCM, TBT, SPS, legal basis, WTO Consistency, MFN, national treatment, discrimination, equal treatment, Non-Discrimination, extraterritorial, outside jurisdiction, foreign producers, Extraterritoriality | E3: Discussion of whether measure conforms with WTO or international legal obligations
B4: Legal | C4: Transparency & Due Process | D4: transparency, notification, consultation, stakeholder engagement, Consumer Information, Disclosure Requirements, Consultation Process, Public Consultation, predictability, certainty, clarity, stable rules, HS Classification Reform, Scope Expansion, Scope Clarification, predictability, certainty, clarity, stable rules, HS Classification Reform, Scope Expansion, Scope Clarification | E4: Calls for advance notice, consultation, procedural fairness, predictability of rules, clarity on rules or measures
B5: Economic | C5: Market Access & Trade Effects | D5: market access, exports, imports, barriers, trade flows, Green Services, Trade Facilitation | E5: Measure affects ability to sell products internationally
B6: Economic | C6: Competitiveness | D6: competitiveness, level playing field, cost disadvantage, SMEs, small business, industry impacts, investment, jobs, relocation, employment, Investment Promotion | E6: Firms or sectors may gain/lose competitive position
B7: Economic | C7: Compliance Costs | D7: compliance cost, administrative burden, reporting burden, Border Carbon Adjustment, Border Carbon Adjustments, Carbon Pricing, ETS, Carbon Tax, Carbon Credits, Carbon Price Deduction, Compliance Costs | E7: Firms incur costs to meet requirements
B8: Development | C8: Capacity Constraints | D8: capacity, institutional constraints, readiness, Capacity Constraints, Technical capacity; Financial Capacity | E8: Developing countries lack ability to comply
B9: Development | C9: Equity & Just Transition | D9: fairness, equity, inclusiveness, just transition, Food Security, Traditional Knowledge, Climate Vulnerability, Sustainable Trade, Energy Transition, S&DT, CBDR, LDCs, developing countries, Small Economies | E9: Distributional effects across countries or groups
B10: Development | C10: Policy Space | D10: policy space, industrialisation, development priorities, Structural Constraints, Sustainable Development, Green Growth, domestic conditions | E10: Concern that measure restricts development choices
B11: Technical | C11: MRV methodologies | D11: MRV, emissions calculation, carbon intensity, monitoring, verification, reporting, Carbon Accounting, Carbon Measurement Standards, traceability, tracking, databases, product passport, Digital Services, methodology, benchmark, default values, certification, accreditation, verification, Verification Framework, ESG Standards, Conformity Assessment, Certification Schemes | E11: Debate on measuring emissions
B12: Technical | C12: Technical Basis | D12: science-based, evidence-based, risk assessment, Evidence Requirements | E12: Requests for scientific justification
B13: Regulatory | C13: Interoperability & Equivalence | D13: interoperability, equivalence, compatibility, harmonisation, alignment, common standards, Sustainability Standards, International Standards, Regulatory Alignment, Regulatory Architecture, Climate-Related Measures, Policy Alignment, mutual recognition, foreign standards, Recognition of Foreign Carbon Pricing Systems, Recognition of Foreign Regulatory Systems, Recognition of Foreign Systems, fragmentation, overlapping requirements, Biodiversity Governance, Access and Benefit Sharing, Bioeconomy Governance, Standards Fragmentation, Regulatory Coherence | E13: Different systems need to function together
... B16: Political Economy | C16: Economic Security & Strategic Autonomy | D16: economic security, strategic autonomy, resilience, industrial policy, friendshoring, reshoring, technology leadership, supply chain, value chain, sourcing, resilience, Green Supply Chains, Supply Chain Resilience, reciprocal tariffs, national security, economic security. | E16: Measure justified by security or strategic concerns
